Workbook

Sheet LIQUIDACIÓN
A1: DESTINO | B1: MISIÓN | C1: SALIDA | F1: REGRESO | I1: VIÁTICO | K1: IMPORTE | L1: CHOFER | M1: ENFERMERA | N1: IMPORTE | O1: MÉD/ADM. | P1: IMPORTE
B2: MISIÒN | C2: DIA | D2: MES | E2: HORA | F2: DIA | G2: MES | H2: HORA | I2: DIAS | J2: CUOTA
A4: SANTA FE | B4: COMISION DE SERVICIOS | C4: 2 | D4: 6 | E4: 4.15 | F4: 2 | G4: 6 | H4: 16,30 | I4: 1 | J4: 86053 | K4: =J4*I4 -> 86053 | L4: RAMA
A5: SANTA FE | B5: SERRA GUADALUPE | C5: 2 | D5: 6 | E5: 8 | F5: 3 | G5: 5 | H5: 14,30 | I5: 0.5 | J5: 86053 | K5: =J5*I5 -> 43026.5 | L5: CRISTIAN | M5: CANEPA | N5: =K5 -> 43026.5
A6: TOSTADO | B6: SEGOBIA ARTURO | C6: 2 | D6: 6 | E6: 04,00 | F6: 2 | G6: 6 | H6: 10,05 | I6: 0.5 | J6: 86053 | K6: =J6*I6 -> 43026.5 | L6: ALEJANDRO | M6: BARBAGLIA | N6: =K6 -> 43026.5
A7: RAFAELA | B7: MARIA JOSE | C7: 2 | D7: 6 | E7: 19,00 | F7: 3 | G7: 6 | H7: 01,00 | I7: 0.5 | J7: 86053 | K7: =J7*I7 -> 43026.5 | L7: ALEJANDRO | M7: LOPEZE SALOME | N7: =K7 -> 43026.5
A8: RAFAELA | B8: VERON ROSA ISABEL | C8: 4 | D8: 6 | E8: 09,00 | F8: 4 | G8: 6 | H8: 15,15 | I8: 0.5 | J8: 86053 | K8: =J8*I8 -> 43026.5 | L8: MATEOS | M8: CANEPA | N8: 42183
A9: RAFAELA | B9: CANTRERA RUBEN | C9: 5 | D9: 6 | E9: 03,45 | F9: 5 | G9: 6 | H9: 10,00 | I9: 0.5 | J9: 86053 | K9: =J9*I9 -> 43026.5 | L9: ALEJANDRO | M9: CANEPA | N9: =K9 -> 43026.5
A10: RAFAELA | B10: AGUSTINA CORONEL | C10: 5 | D10: 6 | E10: 17:00 | F10: 5 | G10: 6 | H10: 23,45 | I10: 0.5 | J10: 86053 | K10: =J10*I10 -> 43026.5 | L10: TOLEDO | M10: VIVANI | N10: =K10 -> 43026.5
A11: RAFAELA | B11: MARTINEZ JOAQUIN | C11: 5 | D11: 6 | E11: 09,00 | F11: 5 | G11: 6 | H11: 15.15 | I11: 0.5 | J11: 86053 | K11: =J11*I11 -> 43026.5 | L11: RAMA | M11: LOPEZE SALOME | N11: =K11 -> 43026.5
A12: SANTA FE | B12: MERELES FACUNDO | C12: 5 | D12: 6 | E12: 19,45 | F12: 6 | G12: 6 | H12: 02,00 | I12: 0.5 | J12: 86053 | K12: =J12*I12 -> 43026.5 | L12: ALEJANDRO | M12: CANEPA | N12: =K12 -> 43026.5
A13: RAFAELA | B13: RIOS ANDREA | C13: 6 | D13: 6 | E13: 09,00 | F13: 6 | G13: 6 | H13: 16,00 | I13: 0.5 | J13: 86053 | K13: =J13*I13 -> 43026.5 | L13: TOLEDO | M13: RAMIREZ | N13: =K12 -> 43026.5 | O13: CATTANEO | P13: =J13/2 -> 43026.5
A14: RAFAELA | B14: SOSA LUDMILA | C14: 6 | D14: 6 | E14: 17,00 | F14: 6 | G14: 6 | H14: 23,45 | I14: 0.5 | J14: 86053 | K14: =J14*I14 -> 43026.5 | L14: TOLEDO | M14: RAMIREZ | N14: =K14 -> 43026.5
A15: RAFAELA | B15: GONZALES GLADIS | C15: 6 | D15: 6 | E15: 10,40 | F15: 6 | G15: 6 | H15: 16,50 | I15: 0.5 | J15: 86053 | K15: =J15*I15 -> 43026.5 | L15: RAMA | M15: CANEPA | N15: =K15 -> 43026.5
A16: RAFAELA | B16: JUAREZ NANCY | C16: 7 | D16: 6 | E16: 14,30 | F16: 7 | G16: 6 | H16: 20,45 | I16: 0.5 | J16: 86053 | K16: =J16*I16 -> 43026.5 | L16: RAMA | M16: CANEPA | N16: =K16 -> 43026.5
A17: RAFAELA | B17: VERCELANE FACUNDO | C17: 7 | D17: 6 | E17: 19,30 | F17: 8 | G17: 6 | H17: 02,00 | I17: 0.5 | J17: 86053 | K17: =J17*I17 -> 43026.5 | L17: ALEJANDRO | M17: LOPEZE SALOME | N17: =K17 -> 43026.5
A18: SANTA FE | B18: TORRES JONAS | C18: 8 | D18: 6 | E18: 09,00 | F18: 8 | G18: 6 | H18: 15,15 | I18: 0.5 | J18: 86053 | K18: =J18*I18 -> 43026.5 | L18: MATEOS | M18: CANEPA | N18: =K18 -> 43026.5
A19: SANTA FE | B19: COMISION DE SERVICIOS | C19: 9 | D19: 6 | E19: 04,15 | F19: 9 | G19: 6 | H19: 16,25 | I19: 0.5 | J19: 86053 | K19: =J19*I19 -> 43026.5 | L19: MATEOS
A20: SANTA FE | B20: CORREA EMILIO | C20: 9 | D20: 6 | E20: 05,30 | F20: 9 | G20: 6 | H20: 11,40 | I20: 0.5 | J20: 86053 | K20: =J20*I20 -> 43026.5 | L20: ALEJANDRO
A21: SANTA FE | B21: MUÑOZ MANUEL | C21: 9 | D21: 6 | E21: 15,00 | F21: 9 | G21: 6 | H21: 21,15 | I21: 0.5 | J21: 86053 | K21: =J21*I21 -> 43026.5 | L21: CRISTIAN
A22: RAFAELA | B22: CAULA OLIVA | C22: 11 | D22: 6 | E22: 10,00 | F22: 11 | G22: 6 | H22: 16,10 | I22: 0.5 | J22: 86053 | K22: =J22*I22 -> 43026.5 | L22: MATEOS | M22: CANEPA | N22: =K22 -> 43026.5 | O22: DE NAPOLI | P22: =J22/2 -> 43026.5
A23: SANTA FE | B23: ROFT CLARA | C23: 12 | D23: 6 | E23: 00,30 | F23: 12 | G23: 6 | H23: 07,00 | I23: 0.5 | J23: 86053 | K23: =J23*I23 -> 43026.5 | L23: ALEJANDRO | M23: LOPEZE SALOME | N23: =K23 -> 43026.5
A24: RAFAELA | B24: SABA GUILLERMO | C24: 13 | D24: 6 | E24: 08,50 | F24: 13 | G24: 6 | H24: 15,00 | I24: 0.5 | J24: 86053 | K24: =J24*I24 -> 43026.5 | L24: MATEOS | M24: RAMIREZ | N24: =K24 -> 43026.5
A25: TOSTADO | B25: ZARATE FATIMA | C25: 14 | D25: 6 | E25: 08,00 | F25: 14 | G25: 6 | H25: 13,30 | I25: 0.5 | J25: 86053 | K25: =J25*I25 -> 43026.5 | L25: OLIVARES
A26: SANTA FE | B26: COMISION DE SERVICIOS | C26: 16 | D26: 6 | E26: 04,15 | F26: 16 | G26: 6 | H26: 16,30 | I26: 1 | J26: 86053 | K26: =J26*I26 -> 86053 | L26: RAMA
A27: SANTA FE | B27: CORTES LUCAS | C27: 16 | D27: 6 | E27: 11,00 | F27: 16 | G27: 6 | H27: 17,40 | I27: 0.5 | J27: 86053 | K27: =J27*I27 -> 43026.5 | L27: CRISTIAN | M27: CANEPA | N27: =K27 -> 43026.5
A28: RAFAELA | B28: CASTILLO GONZALES | C28: 17 | D28: 6 | E28: 06,00 | F28: 17 | G28: 6 | H28: 12,20 | I28: 0.5 | J28: 86053 | K28: =J28*I28 -> 43026.5 | L28: MATEOS | M28: CANEPA | N28: =K28 -> 43026.5
A29: RAFAELA | B29: CORREA EZEQUIEL | C29: 17 | D29: 6 | E29: 12,30 | F29: 17 | G29: 6 | H29: 19,00 | I29: 0.5 | J29: 86053 | K29: =J29*I29 -> 43026.5 | L29: ALEJANDRO | M29: RAMIREZ | N29: =K29 -> 43026.5
A30: RAFAELA | B30: COMISION DE SERVICIOS | C30: 18 | D30: 6 | E30: 08,00 | F30: 18 | G30: 6 | H30: 15,30 | I30: 0.5 | J30: 86053 | K30: =J30*I30 -> 43026.5 | L30: OLIVARES
A31: RAFAELA | B31: BRACACCINI ENZO | C31: 18 | D31: 6 | E31: 14,30 | F31: 18 | G31: 6 | H31: 20,40 | I31: 0.5 | J31: 86053 | K31: =J31*I31 -> 43026.5 | L31: MATEOS | M31: CANEPA | N31: =K31 -> 43026.5
A32: RAFAELA | B32: MARTINEZ JOAQUIN | C32: 18 | D32: 6 | E32: 17,15 | F32: 18 | G32: 6 | H32: 23,45 | I32: 0.5 | J32: 86053 | K32: =J32*I32 -> 43026.5 | L32: TOLEDO | M32: VIVIANI | N32: =K32 -> 43026.5
A33: SANTA FE | B33: OJEDA FAUSTO | C33: 20 | D33: 6 | E33: 20,30 | F33: 21 | G33: 6 | H33: 03,30 | I33: 0.5 | J33: 86053 | K33: =J33*I33 -> 43026.5 | L33: FONTANELLAZ | M33: RAMIREZ | N33: =K33 -> 43026.5
A34: RAFAELA | B34: VELAZQUEZ NICOLE | C34: 20 | D34: 6 | E34: 23,45 | F34: 21 | G34: 6 | H34: 06,00 | I34: 0.5 | J34: 86053 | K34: =J34*I34 -> 43026.5 | L34: OLIVARES | M34: CANEPA | N34: =K34 -> 43026.5
A35: SANTA FE | B35: VELAZQUEZ NICOLE | C35: 21 | D35: 6 | E35: 22,15 | F35: 22 | G35: 6 | H35: 05,00 | I35: 0.5 | J35: 86053 | K35: =J35*I35 -> 43026.5 | L35: TOLEDO | M35: DOBANTON | N35: =K35 -> 43026.5
A36: RAFAELA | B36: MUGNA MARIA | C36: 21 | D36: 6 | E36: 15.20 | F36: 21 | G36: 6 | H36: 22,00 | I36: 0.5 | J36: 86053 | K36: =J36*I36 -> 43026.5 | L36: TOLEDO | M36: CANEPA | N36: =K36 -> 43026.5 | O36: BORSINI | P36: =J36/2 -> 43026.5
A37: SANTA FE | B37: LAGGER JOSEFIN | C37: 22 | D37: 6 | E37: 08,00 | F37: 22 | G37: 6 | H37: 14,15 | I37: 0.5 | J37: 86053 | K37: =J37*I37 -> 43026.5 | L37: CRISTIAN | M37: CANEPA | N37: =K37 -> 43026.5
A38: SANTA FE | B38: COMISION DE SERVICIOS | C38: 23 | D38: 6 | E38: 04,15 | F38: 23 | G38: 6 | H38: 16,30 | I38: 1 | J38: 86053 | K38: =J38*I38 -> 86053 | L38: MATEOS
A39: RAFAELA | B39: CORONEL FLORENCIA | C39: 23 | D39: 6 | E39: 09,00 | F39: 23 | G39: 6 | H39: 15,20 | I39: 0.5 | J39: 86053 | K39: =J39*I39 -> 43026.5 | L39: RAMA | M39: LOPEZE SALOME | N39: =K39 -> 43026.5
A40: RAFAELA | B40: ZALAZAR GONZALO | C40: 23 | D40: 6 | E40: 10,00 | F40: 23 | G40: 6 | H40: 20,05 | I40: 0.5 | J40: 86053 | K40: =J40*I40 -> 43026.5 | L40: FONTANELLAZ | M40: RAMIREZ | N40: =K40 -> 43026.5
A41: RAFAELA | B41: FERNANDEZ JESICA | C41: 24 | D41: 6 | E41: 18,00 | F41: 25 | G41: 6 | H41: 00,35 | I41: 0.5 | J41: 86053 | K41: =J41*I41 -> 43026.5 | L41: ALEJANDRO | M41: CANEPA | N41: =K41 -> 43026.5
...

Sheet DETALLE
A1: RELACION DE GASTOS PARA HOSPITAL JULIO CESAR VILLANUEVA
A2: DE SAN CRISTÓBAL | C2: PARTIDA PARCIAL
A3: Racionamiento
A4: Bienes | C4: Viáticos JUNIO 2026
A5: Servicios | B5: X
A6: PROVEEDOR | B6: FECHA | C6: COMPROBANTE | D6: NRO.CHEQUE | E6: FOLIO | F6: IMPORTE
A7: ALEJANDRO JOSÉ | B7: 31/06/2026 | C7: Planilla de viáticos | F7: ='ALEJANDRO J'!I30 -> 590562
A8: TOLEDO LUCIANO | B8: 31/06/2026 | C8: Planilla de viáticos | F8: =TOLEDO!I30 -> 253098
A9: LODI CRISTIAN | B9: 31/06/2026 | C9: Planilla de viáticos | F9: =LODI!I30 -> 168732
A10: OLIVARES MARCELO | B10: 31/06/2026 | C10: Planilla de viáticos | F10: ='OLIVARES M'!I30 -> 126549
A11: RAMA MANUEL | B11: 31/06/2026 | C11: Planilla de viáticos | F11: ='RAMA M'!I30 -> 506196
A12: MATEOS JUAN CRUZ | B12: 31/06/2026 | C12: Planilla de viáticos | F12: =MATEOS!I32 -> 506196
A13: FONTANELLAZ CLAUDIO | B13: 31/06/2026 | C13: Planilla de viáticos | F13: ='FONTANELLAZ C'!I30 -> 168732
A14: BARBAGLIA LORENA | B14: 31/06/2026 | C14: Planilla de viáticos | F14: ='BARBAGLIA L'!I32 -> 42183
A15: DOBANTON LAURA | B15: 31/06/2026 | C15: Planilla de viáticos | F15: =DOBANTON!I33 -> 84366
A16: ORDOÑEZ MARIA SOLEDAD | B16: 31/06/2026 | C16: Planilla de viáticos | F16: ='ORDOÑEZ S'!I33 -> 84366
A17: CANEPA VERONICA | B17: 31/06/2026 | C17: Planilla de viáticos | F17: =CANEPA!I31 -> 717111
A18: RAMIREZ MARIA | B18: 46173 | C18: Planilla de viáticos | F18: =RAMIREZ!I32 -> 379647
A19: LOPEZ SALOME | B19: 31/06/2026 | C19: Planilla de viáticos | F19: =LOPEZE!I33 -> 337464
A20: VIVIANI ARACELI | B20: 31/06/2026 | C20: Planilla de viáticos | F20: =VIVIANI!I33 -> 84366
A21: BORSINI ARMANDO | B21: 31/06/2026 | C21: Planilla de viáticos | F21: =BORSINI!I31 -> 42183
A22: EYVASTRE MARIELA | B22: 31/06/2026 | C22: Planilla de viáticos | F22: =EYVASTRE!I31 -> 42183
A23: DE NAPOLI CLAUDIA | B23: 31/06/2026 | C23: Planilla de viáticos | F23: ='DE NAPOLI'!I31 -> 42183
A24: CATTANEO RICARDO | B24: 31/06/2026 | C24: Planilla de viáticos | F24: =CATTANEO!I31 -> 42183
A25: BACA JIMENEZ DENAS | B25: 31/06/2026 | C25: Planilla de viáticos | F25: =BACAJIMENEZ!I31 -> 42183
A26: NICOLA CAMILA | B26: 31/06/2026 | C26: Planilla de viáticos | F26: =NICOLA!I31 -> 42183
A27: VALLI LARA | B27: 31/06/2026 | C27: Planilla de viáticos | F27: =AMBROSINI!I31 -> 42183
F29: =SUM(F7:F28) -> 4344849
A31: SAN CRISTÓBAL, JUNIO DE 2026 | D31: .........................................
D32: FIRMA SUPERIOR
D35: ..........................................
D36: FIRMA EMPLEADO

Sheet USPRUNG
A1: DIRECCION: COCHABAMBA 1456 - SAN CRISTOBAL
A2: AGENTE: USPRUNG ARIEL | J2: CARGO
A3: DESTINO: RAFAELA | J3: CHOFER
A4: MISION: PACIENTES VARIOS | J4: ITEM | K4: SUELDO
A6: ='ALEJANDRO J'!A6:J6 -> 0
A7: SALIDA | D7: REGRESO | G7: VIÁTICO | I7: IMPORTE | J7: OBSERVACIONES
A8: DIA | B8: MES | C8: HORA | D8: DIA | E8: MES | F8: HORA | G8: DÍAS | H8: CUOTA
A9: 14 | B9: 8 | C9: 14,40 | D9: 14 | E9: 8 | F9: 19,30 | G9: 0.25 | H9: 67683 | I9: 16920.75
A10: 27 | B10: 8 | C10: 21 | D10: 28 | E10: 8 | F10: 1,04 | G10: 0.25 | H10: 67683 | I10: 16920.75
A25: FECHA | C25: N° COMPROBANTE | E25: DETALLE
A29: TOTAL $ | I29: 0
A32: SON PESOS : TREINTA Y TRES MIL OCHOCIENTOS CUARENTA Y UNO C/ 50/100
I35: .........................................
I36: FIRMA SUPERIOR
A39: RECIBI EL IMPORTE QUE ARROJA LA PLANILLA | I39: ..........................................
A40: ='ALEJANDRO J'!A41 -> SAN CRISTOBAL, JUNIO DE 2026 | I40: FIRMA EMPLEADO

Sheet TOLEDO
A1: DIRECCION: COCHABAMBA 1456 - SAN CRISTOBAL
A2: AGENTE: TOLEDO LUCIANO | J2: CARGO
A3: DESTINO: SANTA FE - RAFAELA | J3: CHOFER
A4: MISION: PACIENTES VARIOS | J4: ITEM | K4: SUELDO
A6: VIATICOS MES JUNIO 2026
A7: SALIDA | D7: REGRESO | G7: VIÁTICO | I7: IMPORTE | J7: OBSERVACIONES
A8: DIA | B8: MES | C8: HORA | D8: DIA | E8: MES | F8: HORA | G8: DÍAS | H8: CUOTA
A9: 5 | B9: 6 | C9: 17:00 | D9: 5 | E9: 6 | F9: 23,45 | G9: 0.5 | H9: 84366 | I9: 42183
A10: 6 | B10: 6 | C10: 09,00 | D10: 6 | E10: 6 | F10: 16,00 | G10: 0.5 | H10: 84366 | I10: 42183
A11: 6 | B11: 6 | C11: 17,00 | D11: 6 | E11: 6 | F11: 23,45 | G11: 0.5 | H11: 84366 | I11: 42183
A12: 18 | B12: 6 | C12: 17,15 | D12: 18 | E12: 6 | F12: 23,45 | G12: 0.5 | H12: 84366 | I12: 42183
A13: 21 | B13: 6 | C13: 22,15 | D13: 22 | E13: 6 | F13: 05,00 | G13: 0.5 | H13: 84366 | I13: 42183
A14: 21 | B14: 6 | C14: 15.20 | D14: 21 | E14: 6 | F14: 22,00 | G14: 0.5 | H14: 84366 | I14: 42183
A26: FECHA | C26: N° COMPROBANTE | E26: DETALLE
A30: TOTAL $ | I30: =SUM(I9:I23) -> 253098
A32: SON PESOS: DOSCIENTOS CINCUENTA Y TRES MIL NOVENTA Y OCHO C/00 CTVOS
I35: .........................................
I36: FIRMA SUPERIOR
A39: RECIBI EL IMPORTE QUE ARROJA LA PLANILLA | I39: ..........................................
A40: SAN CRISTOBAL JUNIO 2026 | I40: FIRMA EMPLEADO

Sheet LODI
A1: DIRECCION: COCHABAMBA 1456 - SAN CRISTOBAL
A2: AGENTE: LODI CRISTIAN | J2: CARGO
A3: DESTINO: SANTA FE - RAFAELA | J3: CHOFER
A4: MISION: PACIENTES VARIOS | J4: ITEM | K4: SUELDO
A6: VIATICOS MES JUNIO 2026
D7: REGRESO | G7: VIÁTICO | I7: IMPORTE | J7: OBSERVACIONES
A8: DIA | B8: MES | C8: HORA | D8: DIA | E8: MES | F8: HORA | G8: DÍAS | H8: CUOTA
A9: 2 | B9: 6 | C9: 8 | D9: 3 | E9: 5 | F9: 14,30 | G9: 0.5 | H9: 84366 | I9: 42183
A10: 9 | B10: 6 | C10: 15,00 | D10: 9 | E10: 6 | F10: 21,15 | G10: 0.5 | H10: 84366 | I10: 42183
A11: 16 | B11: 6 | C11: 11,00 | D11: 16 | E11: 6 | F11: 17,40 | G11: 0.5 | H11: 84366 | I11: 42183
A12: 22 | B12: 6 | C12: 08,00 | D12: 22 | E12: 6 | F12: 14,15 | G12: 0.5 | H12: 84366 | I12: 42183
A26: FECHA | C26: N° COMPROBANTE | E26: DETALLE
A30: TOTAL $ | I30: =SUM(I9:I23) -> 168732
A33: SON PESOS: CIENTO SESENTA Y OCHO MIL SETECIENTOS TREINTA Y DOS C/00 CTVOS
I36: .........................................
I37: FIRMA SUPERIOR
A39: RECIBI EL IMPORTE QUE ARROJA LA PLANILLA
A40: SAN CRISTOBAL JUNIO 2026 | I40: FIRMA EMPLEADO

Sheet CURBELA E
A1: DIRECCION: COCHABAMBA 1456 - SAN CRISTOBAL
A2: AGENTE: GIRAUDO JUAN ANTONIO | J2: CARGO
A3: DESTINO: SANTA FE - RAFAELA | J3: CHOFER
A4: MISION: PACIENTES VARIOS | J4: ITEM | K4: SUELDO
A6: VIATICOS MES MAYO 2026
A7: SALIDA | D7: REGRESO | G7: VIÁTICO | I7: IMPORTE | J7: OBSERVACIONES
A8: DIA | B8: MES | C8: HORA | D8: DIA | E8: MES | F8: HORA | G8: DÍAS | H8: CUOTA
A9: 6 | B9: 5 | C9: 12,45 | D9: 6 | E9: 5 | F9: 18,50 | G9: 0.5 | H9: 83166 | I9: =H9*G9 -> 41583
A26: FECHA | C26: N° COMPROBANTE | E26: DETALLE
A30: TOTAL $ | I30: =SUM(I9:I23) -> 41583
A33: SON PESOS:CUARENTA Y UN MIL QUINIENTOS OCHENTA Y TRES C/00 CTVO
I36: .........................................
I37: FIRMA SUPERIOR
A39: RECIBI EL IMPORTE QUE ARROJA LA PLANILLA
A40: SAN CRISTOBAL MAYO 2026 | I40: FIRMA EMPLEADO

Sheet OLIVARES M
A1: DIRECCION: COCHABAMBA 1456 - SAN CRISTOBAL
A2: AGENTE: OLIVARES MARCELO | J2: CARGO
A3: DESTINO: SANTA FE - RAFAELA | J3: CHOFER
A4: MISION: PACIENTES VARIOS | J4: ITEM | K4: SUELDO
A6: VIATICOS MES JUNIO 2026
A7: SALIDA | D7: REGRESO | G7: VIÁTICO | I7: IMPORTE | J7: OBSERVACIONES
A8: DIA | B8: MES | C8: HORA | D8: DIA | E8: MES | F8: HORA | G8: DÍAS | H8: CUOTA
A9: 14 | B9: 6 | C9: 08,00 | D9: 14 | E9: 6 | F9: 13,30 | G9: 0.5 | H9: 84366 | I9: 42183
A10: 18 | B10: 6 | C10: 08,00 | D10: 18 | E10: 6 | F10: 15,30 | G10: 0.5 | H10: 84366 | I10: 42183
A11: 20 | B11: 6 | C11: 23,45 | D11: 21 | E11: 6 | F11: 06,00 | G11: 0.5 | H11: 84366 | I11: 42183
A26: FECHA | C26: N° COMPROBANTE | E26: DETALLE
A30: TOTAL $ | I30: =SUM(I9:I23) -> 126549
A33: SON PESOS: CIENTO VEINTISÉIS MIL QUINIENTOS CUARENTA Y NUEVE C/00 CTVOS.-
I36: .........................................
I37: FIRMA SUPERIOR
A40: RECIBI EL IMPORTE QUE ARROJA LA PLANILLA | I40: ..........................................
A41: SAN CRISTOBAL JUNIO 2026 | I41: FIRMA EMPLEADO

Sheet FONTANELLAZ C
A1: DIRECCION: COCHABAMBA 1456 - SAN CRISTOBAL
A2: AGENTE: FONTANELLAZ CLAUDIO | J2: CARGO
A3: DESTINO: SANTA FE - RAFAELA | J3: CHOFER
A4: MISION: PACIENTES VARIOS | J4: ITEM | K4: SUELDO
A6: VIATICOS MES JUNIO 2026
A7: SALIDA | D7: REGRESO | G7: VIÁTICO | I7: IMPORTE | J7: OBSERVACIONES
A8: DIA | B8: MES | C8: HORA | D8: DIA | E8: MES | F8: HORA | G8: DÍAS | H8: CUOTA
A9: 20 | B9: 6 | C9: 20,30 | D9: 21 | E9: 6 | F9: 03,30 | G9: 0.5 | H9: 84366 | I9: 42183
A10: 23 | B10: 6 | C10: 10,00 | D10: 23 | E10: 6 | F10: 20,05 | G10: 0.5 | H10: 84366 | I10: 42183
A11: 25 | B11: 6 | C11: 03,45 | D11: 25 | E11: 6 | F11: 10,00 | G11: 0.5 | H11: 84366 | I11: 42183
A12: 26 | B12: 6 | C12: 10,30 | D12: 26 | E12: 6 | F12: 21,30 | G12: 0.5 | H12: 84366 | I12: 42183
A26: FECHA | C26: N° COMPROBANTE | E26: DETALLE
A30: TOTAL $ | I30: =SUM(I9:I23) -> 168732
A33: SON PESOS: CIENTO SESENTA Y OCHO MIL SETESCIENTOS TREINTA Y DOS C/00 CTVOS.-
I36: .........................................
I37: FIRMA SUPERIOR
A40: RECIBI EL IMPORTE QUE ARROJA LA PLANILLA | I40: ..........................................
A41: SAN CRISTOBAL JUNIO 2026 | I41: FIRMA EMPLEADO

Sheet ALEJANDRO J
A1: DIRECCION: COCHABAMBA 1456 - SAN CRISTOBAL
A2: AGENTE: ALEJANDRO JOSÉ | J2: CARGO
A3: DESTINO: RAFAELA -SANTA FE | J3: CHOFER
A4: MISION: PACIENTES VARIOS
A5: VIATICOS MES DE JUNIO 2026
A7: SALIDA | D7: REGRESO | G7: VIÁTICO | I7: IMPORTE | J7: OBSERVACIONES
A8: DIA | B8: MES | C8: HORA | D8: DIA | E8: MES | F8: HORA | G8: DÍAS | H8: CUOTA
A9: 2 | B9: 6 | C9: 04,00 | D9: 2 | E9: 6 | F9: 10,05 | G9: 0.5 | H9: 84366 | I9: 42183
A10: 2 | B10: 6 | C10: 19,00 | D10: 3 | E10: 6 | F10: 01,00 | G10: 0.5 | H10: 84366 | I10: 42183
A11: 5 | B11: 6 | C11: 03,45 | D11: 5 | E11: 6 | F11: 10,00 | G11: 0.5 | H11: 84366 | I11: 42183
A12: 5 | B12: 6 | C12: 19,45 | D12: 6 | E12: 6 | F12: 02,00 | G12: 0.5 | H12: 84366 | I12: 42183
A13: 7 | B13: 6 | C13: 19,30 | D13: 8 | E13: 6 | F13: 02,00 | G13: 0.5 | H13: 84366 | I13: 42183
A14: 9 | B14: 6 | C14: 05,30 | D14: 9 | E14: 6 | F14: 11,40 | G14: 0.5 | H14: 84366 | I14: 42183
A15: 12 | B15: 6 | C15: 00,30 | D15: 12 | E15: 6 | F15: 07,00 | G15: 0.5 | H15: 84366 | I15: 42183
A16: 17 | B16: 6 | C16: 12,30 | D16: 17 | E16: 6 | F16: 19,00 | G16: 0.5 | H16: 84366 | I16: 42183
A17: 24 | B17: 6 | C17: 18,00 | D17: 25 | E17: 6 | F17: 00,35 | G17: 0.5 | H17: 84366 | I17: 42183
A18: 24 | B18: 6 | C18: 00,30 | D18: 24 | E18: 6 | F18: 07,00 | G18: 0.5 | H18: 84366 | I18: 42183
A19: 25 | B19: 6 | C19: 00,40 | D19: 25 | E19: 6 | F19: 07,00 | G19: 0.5 | H19: 84366 | I19: 42183
A20: 26 | B20: 6 | C20: 03,00 | D20: 26 | E20: 6 | F20: 09,15 | G20: 0.5 | H20: 84366 | I20: 42183
... A22: 30 | B22: 6 | C22: 10,30 | D22: 30 | E22: 6 | F22: 17,00 | G22: 0.5 | H22: 84366 | I22: 42183
A30: TOTAL $ | I30: =SUM(I9:I25) -> 590562
A33: SON PESOS: QUINIENTOS NOVENTA MIL QUINIENTOS SESENTA Y DOS. C/00 CTVOS.-
H36: ……………………………………….
H37: FIRMA SUPERIOR
A40: RECIBI EL IMPORTE QUE ARROJA LA PLANILLA | H40: ............................................
A41: SAN CRISTOBAL, JUNIO DE 2026 | H41: FIRMA EMPLEADO

Sheet MATEOS
A1: DIRECCION: COCHABAMBA 1456 - SAN CRISTOBAL
A2: AGENTE: MATEOS JUAN CRUZ | J2: CARGO
A3: DESTINO: RAFAELA -SANTA FE | J3: CHOFER
A4: MISION: PACIENTES VARIOS
A5: VIATICOS MES JUNIO 2026
A7: SALIDA | D7: REGRESO | G7: VIÁTICO | I7: IMPORTE | J7: OBSERVACIONES
A8: DIA | B8: MES | C8: HORA | D8: DIA | E8: MES | F8: HORA | G8: DÍAS | H8: CUOTA
A9: 4 | B9: 6 | C9: 09,00 | D9: 4 | E9: 6 | F9: 15,15 | G9: 0.5 | H9: 84366 | I9: 42183
A10: 8 | B10: 6 | C10: 09,00 | D10: 8 | E10: 6 | F10: 15,15 | G10: 0.5 | H10: 84366 | I10: 42183
A11: 9 | B11: 6 | C11: 04,15 | D11: 9 | E11: 6 | F11: 16,25 | G11: 0.5 | H11: 84366 | I11: 42183
A12: 11 | B12: 6 | C12: 10,00 | D12: 11 | E12: 6 | F12: 16,10 | G12: 0.5 | H12: 84366 | I12: 42183
A13: 13 | B13: 6 | C13: 08,50 | D13: 13 | E13: 6 | F13: 15,00 | G13: 0.5 | H13: 84366 | I13: 42183
A14: 17 | B14: 6 | C14: 06,00 | D14: 17 | E14: 6 | F14: 12,20 | G14: 0.5 | H14: 84366 | I14: 42183
A15: 18 | B15: 6 | C15: 14,30 | D15: 18 | E15: 6 | F15: 20,40 | G15: 0.5 | H15: 84366 | I15: 42183
A16: 23 | B16: 6 | C16: 04,15 | D16: 23 | E16: 6 | F16: 16,30 | G16: 1 | H16: 84366 | I16: 84366
A17: 27 | B17: 6 | C17: 15,50 | D17: 27 | E17: 6 | F17: 22,00 | G17: 0.5 | H17: 84366 | I17: 42183
A18: 29 | B18: 6 | C18: 15,50 | D18: 29 | E18: 6 | F18: 22,00 | G18: 0.5 | H18: 84366 | I18: 42183
A19: 30 | B19: 6 | C19: 06,30 | D19: 30 | E19: 6 | F19: 13,30 | G19: 0.5 | H19: 84366 | I19: 42183
A32: TOTAL $ | I32: =SUM(I9:I29) -> 506196
A34: SON PESOS: QUINIENTOS SEIS MIL CIENTO NOVENTA Y SEIS C/00 CTVOS
H36: ............................................
I37: FIRMA SUPERIOR
A40: RECIBI EL IMPORTE QUE ARROJA LA PLANILLA | H40: ............................................
A41: SAN CRISTOBAL, JUNIO DE 2026 | I41: FIRMA EMPLEADO

Sheet RAMA M
A1: DIRECCION: COCHABAMBA 1456 - SAN CRISTOBAL
A2: AGENTE: RAMA MANUEL | J2: CARGO
A3: DESTINO: SANTA FE - RAFAELA | J3: CHOFER
A4: MISION: PACIENTES VARIOS | J4: ITEM | K4: SUELDO
A5: VIATICOS MES JUNIO 2026
A7: SALIDA | D7: REGRESO | G7: VIÁTICO | I7: IMPORTE | J7: OBSERVACIONES
A8: DIA | B8: MES | C8: HORA | D8: DIA | E8: MES | F8: HORA | G8: DÍAS | H8: CUOTA
A9: 2 | B9: 6 | C9: 4.15 | D9: 2 | E9: 6 | F9: 16,30 | G9: 1 | H9: 84366 | I9: 84366
A10: 5 | B10: 6 | C10: 09,00 | D10: 5 | E10: 6 | F10: 15.15 | G10: 0.5 | H10: 84366 | I10: 42183
A11: 6 | B11: 6 | C11: 10,40 | D11: 6 | E11: 6 | F11: 16,50 | G11: 0.5 | H11: 84366 | I11: 42183
A12: 7 | B12: 6 | C12: 14,30 | D12: 7 | E12: 6 | F12: 20,45 | G12: 0.5 | H12: 84366 | I12: 42183
A13: 16 | B13: 6 | C13: 04,15 | D13: 16 | E13: 6 | F13: 16,30 | G13: 1 | H13: 84366 | I13: 84366
A14: 23 | B14: 6 | C14: 09,00 | D14: 23 | E14: 6 | F14: 15,20 | G14: 0.5 | H14: 84366 | I14: 42183
A15: 24 | B15: 6 | C15: 09,00 | D15: 24 | E15: 6 | F15: 16,00 | G15: 0.5 | H15: 84366 | I15: 42183
A16: 26 | B16: 6 | C16: 03,10 | D16: 26 | E16: 6 | F16: 09,20 | G16: 0.5 | H16: 84366 | I16: 42183
A17: 30 | B17: 6 | C17: 04,00 | D17: 30 | E17: 6 | F17: 16,15 | G17: 1 | H17: 84366 | I17: 84366
A26: FECHA | C26: N° COMPROBANTE | E26: DETALLE
A30: TOTAL $ | I30: =SUM(I9:I23) -> 506196
A33: SON PESOS: QUINIENTOS SEIS MIL CIENTO NOVENTA Y SEIS C/00 CTVOS.
I36: .........................................
I37: FIRMA SUPERIOR
A40: RECIBI EL IMPORTE QUE ARROJA LA PLANILLA | I40: ..........................................
A41: SAN CRISTOBAL JUNIO 2026 | I41: FIRMA EMPLEADO

Sheet MATEOS J C
A1: DIRECCION: COCHABAMBA 1456 - SAN CRISTOBAL
A2: AGENTE: MATEOS JUAN CRUZ | J2: CARGO
A3: DESTINO: SANTA FE - RAFAELA-CERES | J3: CHOFER
A4: MISION: PACIENTES VARIOS | J4: ITEM | K4: SUELDO
A6: ='ALEJANDRO J'!A6:J6 -> 0
A7: SALIDA | D7: REGRESO | G7: VIÁTICO | I7: IMPORTE | J7: OBSERVACIONES
A8: DIA | B8: MES | C8: HORA | D8: DIA | E8: MES | F8: HORA | G8: DÍAS | H8: CUOTA
A9: 2 | B9: 2 | C9: 10,3 | D9: 2 | E9: 2 | F9: 15,00 | G9: 0.25 | H9: 60845 | I9: 15211.25
A10: 18 | B10: 2 | C10: 13,00 | D10: 18 | E10: 2 | F10: 17,00 | G10: 0.25 | H10: 60845 | I10: 15211.25
A11: 18 | B11: 2 | C11: 8,1 | D11: 18 | E11: 2 | F11: 12,4 | G11: 0.25 | H11: 60845 | I11: 15211.25
A12: 19 | B12: 2 | C12: 4,15 | D12: 19 | E12: 2 | F12: 16,30 | G12: 1 | H12: 60845 | I12: 60845
A13: 20 | B13: 2 | C13: 20,55 | D13: 20 | E13: 2 | F13: 23,55 | G13: 0.25 | H13: 60845 | I13: 15211.25
A14: 20 | B14: 2 | C14: 19,4 | D14: 20 | E14: 2 | F14: 23,40 | G14: 0.25 | H14: 60845 | I14: 15211.25
A15: 21 | B15: 2 | C15: 18 | D15: 22 | E15: 2 | F15: 00,10 | G15: 0.5 | H15: 60845 | I15: 30422.5
A16: 22 | B16: 2 | C16: 19 | D16: 22 | E16: 2 | F16: 23,3 | G16: 0.25 | H16: 60845 | I16: 15211.25
A17: 24 | B17: 2 | C17: 15 | D17: 24 | E17: 2 | F17: 19,3 | G17: 0.25 | H17: 60845 | I17: 15211.25
A18: 25 | B18: 2 | C18: 4,15 | D18: 25 | E18: 2 | F18: 16,3 | G18: 1 | H18: 60845 | I18: 60845
A26: FECHA | C26: N° COMPROBANTE | E26: DETALLE
A30: TOTAL $ | I30: =SUM(I9:I23) -> 258591.25
A33: SON PESOS :DOSCIENTOS CINCUENTA Y OCHO MIL QUINIENTOS NOVENTA Y UNO C/25/100
I36: .......................................
I37: FIRMA SUPERIOR
A40: RECIBI EL IMPORTE QUE ARROJA LA PLANILLA | I40: ......................................
A41: SAN CRISTOBAL, MARZO DE 2025 | I41: FIRMA EMPLEADO

Sheet LAGGER H
A1: DIRECCION: COCHABAMBA 1456 - SAN CRISTOBAL
A2: AGENTE: LAGGER HERNAN | J2: CARGO
A3: DESTINO: SANTA FE -RAFAELA | J3: CHOFER
A4: MISION: PACIENTES VARIOS | J4: ITEM | K4: SUELDO
A5: VIATICOS MES DICIEMBRE 2025
A6: ='ALEJANDRO J'!A6:J6 -> 0
A7: SALIDA | D7: REGRESO | G7: VIÁTICO | I7: IMPORTE | J7: OBSERVACIONES
A8: DIA | B8: MES | C8: HORA | D8: DIA | E8: MES | F8: HORA | G8: DÍAS | H8: CUOTA
A9: 9 | B9: 12 | C9: 15.00 | D9: 9 | E9: 12 | F9: 22.00 | G9: 0.5 | H9: 72808 | I9: =H9*G9 -> 36404
A27: FECHA | C27: N° COMPROBANTE | E27: DETALLE
A31: TOTAL $ | I31: =SUM(I9:I24) -> 36404
A34: SON PESOS:TREINTA Y SEIS MIL CUATROSCIENTOS CUATRO C/00 CTVOS.-
I38: …………………………..........
I39: FIRMA SUPERIOR
A41: RECIBI EL IMPORTE QUE ARROJA LA PLANILLA
A42: SAN CRISTOBAL DICIEMBRE 2025 | I42: .....................................
I43: FIRMA EMPLEADO

Sheet TREJO
A1: DIRECCION: COCHABAMBA 1456 - SAN CRISTOBAL
A2: AGENTE: TREJO FABIAN | J2: CARGO
A3: DESTINO: SANTA FE -RAFAELA | J3: CHOFER
A4: MISION: PACIENTES VARIOS | J4: ITEM | K4: SUELDO
A6: ='ALEJANDRO J'!A6:J6 -> 0
A7: SALIDA | D7: REGRESO | G7: VIÁTICO | I7: IMPORTE | J7: OBSERVACIONES
A8: DIA | B8: MES | C8: HORA | D8: DIA | E8: MES | F8: HORA | G8: DÍAS | H8: CUOTA
A9: 26 | B9: 8 | C9: 20,30 | D9: 27 | E9: 8 | F9: 1 | G9: 0.25 | H9: 67683 | I9: =H9*G9 -> 16920.75
A27: FECHA | C27: N° COMPROBANTE | E27: DETALLE
A31: TOTAL $ | I31: 0
A34: SON PESOS : DIECISEIS MIL NOVECIENTOS VEINTE MIL C/75/100
H37: .........................................
A38: RECIBI EL IMPORTE QUE ARROJA LA PLANILLA | H38: FIRMA SUPERIOR
A39: ='ALEJANDRO J'!A41 -> SAN CRISTOBAL, JUNIO DE 2026
H40: .........................................
H41: FIRMA EMPLEADO

Sheet AVALOS
A1: COMISIÓN DE SERVICIO - VIÁTICOS Y GASTOS
A3: MINISTERIO DE SALUD - HOSPITAL SAN CRISTOBAL
A4: DIRECCION: COCHABAMBA 1456 - SAN CRISTOBAL
A5: AGENTE: AVALOS VERONICA | J5: CARGO
A6: DESTINO: SANTA FE | J6: ENFERMERA
A7: MISION: PACIENTES VARIOS | J7: ITEM | K7: SUELDO
A9: ='ALEJANDRO J'!A6:J6 -> 0
A10: SALIDA | D10: REGRESO | G10: VIÁTICO | I10: IMPORTE | J10: OBSERVACIONES
A11: DIA | B11: MES | C11: HORA | D11: DIA | E11: MES | F11: HORA | G11: DÍAS | H11: CUOTA
A12: 9 | B12: 2 | C12: 22 | D12: 10 | E12: 2 | F12: 04,45 | G12: 0.5 | H12: 60845 | I12: =H12*G12 -> 30422.5
H33: TOTAL | I33: =SUM(I12:I32) -> 30422.5
A35: SON PESOS: TREINTA MIL CUATROSCIENTOS VEINTI DOS C/50 C/100
H37: .........................................
A38: RECIBI EL IMPORTE QUE ARROJA LA PLANILLA | H38: FIRMA SUPERIOR
A39: ='ALEJANDRO J'!A41 -> SAN CRISTOBAL, JUNIO DE 2026
H40: .........................................
H41: FIRMA EMPLEADO

Sheet MIRANDA
A1: COMISIÓN DE SERVICIO - VIÁTICOS Y GASTOS
A3: MINISTERIO DE SALUD - HOSPITAL SAN CRISTOBAL
A4: DIRECCION: COCHABAMBA 1456 - SAN CRISTOBAL
A5: AGENTE: MIRANDA ESTELA | J5: CARGO
A6: DESTINO: RAFAELA | J6: ENFERMERA
A7: MISION: PACIENTES VARIOS | J7: ITEM | K7: SUELDO
A9: ='ALEJANDRO J'!A6:J6 -> 0
A10: SALIDA | D10: REGRESO | G10: VIÁTICO | I10: IMPORTE | J10: OBSERVACIONES
A11: DIA | B11: MES | C11: HORA | D11: DIA | E11: MES | F11: HORA | G11: DÍAS | H11: CUOTA
A12: 23 | B12: 2 | C12: 21,5 | D12: 24 | E12: 2 | F12: 2 | G12: 0.25 | H12: 60845 | I12: =H12*G12 -> 15211.25
H33: TOTAL | I33: =SUM(I12:I32) -> 15211.25
A35: SON PESOS: TREINTA MIL CUATRSOCIENTOS VEINTIDOS C/50 C/100
H37: .........................................
A38: RECIBI EL IMPORTE QUE ARROJA LA PLANILLA | H38: FIRMA SUPERIOR
A39: ='ALEJANDRO J'!A41 -> SAN CRISTOBAL, JUNIO DE 2026
H40: .........................................
H41: FIRMA EMPLEADO

Sheet YEATES
A1: COMISIÓN DE SERVICIO - VIÁTICOS Y GASTOS
A3: MINISTERIO DE SALUD - HOSPITAL SAN CRISTOBAL
A4: DIRECCION: COCHABAMBA 1456 - SAN CRISTOBAL
A5: AGENTE: YEATES VALERIA | J5: CARGO
A6: DESTINO: RAFAELA - SANTA FE | J6: ENFERMERA
A7: MISION: PACIENTES VARIOS | J7: ITEM | K7: SUELDO
A8: 46054
A9: ='ALEJANDRO J'!A6:J6 -> 0
A10: SALIDA | D10: REGRESO | G10: VIÁTICO | I10: IMPORTE | J10: OBSERVACIONES
A11: DIA | B11: MES | C11: HORA | D11: DIA | E11: MES | F11: HORA | G11: DÍAS | H11: CUOTA
A12: 23 | B12: 2 | C12: 17,30 | D12: 23 | E12: 2 | F12: 23,45 | G12: 0.5 | H12: 72808 | I12: =H12*G12 -> 36404
H31: TOTAL | I31: =SUM(I12:I30) -> 36404
A33: SON PESOS:TREINTA Y SEIS MIL CUATROSCIENTOS CUATRO C/00 CTVOS
H35: .........................................
A36: RECIBI EL IMPORTE QUE ARROJA LA PLANILLA | H36: FIRMA SUPERIOR
A37: SAN CRISTOBAL FEBRERO 2026
H38: .........................................
H39: FIRMA EMPLEADO

Sheet CANEPA
A1: COMISIÓN DE SERVICIO - VIÁTICOS Y GASTOS
A3: MINISTERIO DE SALUD - HOSPITAL SAN CRISTOBAL
A4: DIRECCION: COCHABAMBA 1456 - SAN CRISTOBAL
A5: AGENTE: CANEPA VERONICA | J5: CARGO
A6: DESTINO: RAFAELA - SANTA FE | J6: ENFERMERA
A7: MISION: PACIENTES VARIOS | J7: ITEM | K7: SUELDO
A8: 46174
A10: SALIDA | D10: REGRESO | G10: VIÁTICO | I10: IMPORTE | J10: OBSERVACIONES
A11: DIA | B11: MES | C11: HORA | D11: DIA | E11: MES | F11: HORA | G11: DÍAS | H11: CUOTA
A12: 2 | B12: 6 | C12: 8 | D12: 3 | E12: 5 | F12: 14,30 | G12: 0.5 | H12: 84366 | I12: 42183
A13: 4 | B13: 6 | C13: 09,00 | D13: 4 | E13: 6 | F13: 15,15 | G13: 0.5 | H13: 84366 | I13: 42183
A14: 5 | B14: 6 | C14: 03,45 | D14: 5 | E14: 6 | F14: 10,00 | G14: 0.5 | H14: 84366 | I14: 42183
A15: 5 | B15: 6 | C15: 19,45 | D15: 6 | E15: 6 | F15: 02,00 | G15: 0.5 | H15: 84366 | I15: 42183
A16: 6 | B16: 6 | C16: 10,40 | D16: 6 | E16: 6 | F16: 16,50 | G16: 0.5 | H16: 84366 | I16: 42183
A17: 7 | B17: 6 | C17: 14,30 | D17: 7 | E17: 6 | F17: 20,45 | G17: 0.5 | H17: 84366 | I17: 42183
A18: 8 | B18: 6 | C18: 09,00 | D18: 8 | E18: 6 | F18: 15,15 | G18: 0.5 | H18: 84366 | I18: 42183
A19: 11 | B19: 6 | C19: 10,00 | D19: 11 | E19: 6 | F19: 16,10 | G19: 0.5 | H19: 84366 | I19: 42183
A20: 16 | B20: 6 | C20: 11,00 | D20: 16 | E20: 6 | F20: 17,40 | G20: 0.5 | H20: 84366 | I20: 42183
A21: 17 | B21: 6 | C21: 06,00 | D21: 17 | E21: 6 | F21: 12,20 | G21: 0.5 | H21: 84366 | I21: 42183
A22: 18 | B22: 6 | C22: 14,30 | D22: 18 | E22: 6 | F22: 20,40 | G22: 0.5 | H22: 84366 | I22: 42183
A23: 20 | B23: 6 | C23: 23,45 | D23: 21 | E23: 6 | F23: 06,00 | G23: 0.5 | H23: 84366 | I23: 42183
A24: 21 | B24: 6 | C24: 15.20 | D24: 21 | E24: 6 | F24: 22,00 | G24: 0.5 | H24: 84366 | I24: 42183
... A28: 25 | B28: 6 | C28: 00,40 | D28: 25 | E28: 6 | F28: 07,00 | G28: 0.5 | H28: 84366 | I28: 42183
H31: TOTAL | I31: =SUM(I12:I30) -> 717111
A33: SON PESOS:SETECIENTOS DIECISIETE MIL CIENTO ONCE C/00 CTVOS.
H35: .........................................
A36: RECIBI EL IMPORTE QUE ARROJA LA PLANILLA | H36: FIRMA SUPERIOR
A37: SAN CRISTOBAL JUNIO 2026
H38: .........................................
H39: FIRMA EMPLEADO

Sheet BARBAGLIA L
A1: COMISIÓN DE SERVICIO - VIÁTICOS Y GASTOS
A3: MINISTERIO DE SALUD - HOSPITAL SAN CRISTOBAL
A4: DIRECCION: COCHABAMBA 1456 - SAN CRISTOBAL
A5: AGENTE: BARBAGLIA LORENA | J5: CARGO
A6: DESTINO: RAFAELA - SANTA FE | J6: ENFERMERA
A7: MISION: PACIENTES VARIOS | J7: ITEM | K7: SUELDO
A8: 46174
A9: ='ALEJANDRO J'!A6:J6 -> 0
A10: SALIDA | D10: REGRESO | G10: VIÁTICO | I10: IMPORTE | J10: OBSERVACIONES
A11: DIA | B11: MES | C11: HORA | D11: DIA | E11: MES | F11: HORA | G11: DÍAS | H11: CUOTA
A12: 2 | B12: 6 | C12: 04,00 | D12: 2 | E12: 6 | F12: 10,05 | G12: 0.5 | H12: 84366 | I12: =H12*G12 -> 42183
H32: TOTAL | I32: =SUM(I12:I31) -> 42183
A34: SON PESOS: CUARENTA Y DOS MIL CIENTO OCHENTA Y TRES C/00 CTVOS.
H35: .........................................
A36: RECIBI EL IMPORTE QUE ARROJA LA PLANILLA | H36: FIRMA SUPERIOR
A37: SAN CRISTOBAL JUNIO 2026
H38: .........................................
H39: FIRMA EMPLEADO

Sheet ORIETA
A1: COMISIÓN DE SERVICIO - VIÁTICOS Y GASTOS
A3: MINISTERIO DE SALUD - HOSPITAL SAN CRISTOBAL
A4: DIRECCION: COCHABAMBA 1456 - SAN CRISTOBAL
A5: AGENTE: ORIETA JORGELINA | J5: CARGO
A6: DESTINO: RAFAELA- SANTA FE | J6: ENFERMERA
A7: MISION: PACIENTES VARIOS | J7: ITEM | K7: SUELDO
A8: 46113
A9: ='ALEJANDRO J'!A6:J6 -> 0
A10: SALIDA | D10: REGRESO | G10: VIÁTICO | I10: IMPORTE | J10: OBSERVACIONES
A11: DIA | B11: MES | C11: HORA | D11: DIA | E11: MES | F11: HORA | G11: DÍAS | H11: CUOTA
A12: 30 | B12: 4 | C12: 12,00 | D12: 30 | E12: 4 | F12: 18,15 | G12: 0.5 | H12: 81166 | I12: =H12*G12 -> 40583
H33: TOTAL | I33: =SUM(I12:I32) -> 40583
A35: SON PESOS: CUARENTA MIL QUINIENTOS OCHENTA Y TRES C/00 CTVOS.
H37: .........................................
A38: RECIBI EL IMPORTE QUE ARROJA LA PLANILLA | H38: FIRMA SUPERIOR
A39: SAN CRISTOBAL ABRIL 2026
H40: .........................................
H41: FIRMA EMPLEADO

Sheet ORDOÑEZ S
A1: COMISIÓN DE SERVICIO - VIÁTICOS Y GASTOS
A3: MINISTERIO DE SALUD - HOSPITAL SAN CRISTOBAL
A4: DIRECCION: COCHABAMBA 1456 - SAN CRISTOBAL
A5: AGENTE: ORDOÑEZ MARIA SOLEDAD | J5: CARGO
A6: DESTINO: RAFAELA - SANTA FE | J6: ENFERMERA
A7: MISION: PACIENTES VARIOS | J7: ITEM | K7: SUELDO
A8: 46174
A9: ='ALEJANDRO J'!A6:J6 -> 0
A10: SALIDA | D10: REGRESO | G10: VIÁTICO | I10: IMPORTE | J10: OBSERVACIONES
A11: DIA | B11: MES | C11: HORA | D11: DIA | E11: MES | F11: HORA | G11: DÍAS | H11: CUOTA
A12: 25 | B12: 6 | C12: 03,45 | D12: 25 | E12: 6 | F12: 10,00 | G12: 0.5 | H12: 84366 | I12: 42183
A13: 30 | B13: 6 | C13: 10,30 | D13: 30 | E13: 6 | F13: 17,00 | G13: 0.5 | H13: 84366 | I13: 42183
H33: TOTAL | I33: =SUM(I12:I32) -> 84366
A35: SON PESOS: OCHENTA Y CUATRO MIL TRESCIENTOS SESENTA Y SEIS C/50 CTVOS.-
H37: .........................................
A38: RECIBI EL IMPORTE QUE ARROJA LA PLANILLA | H38: FIRMA SUPERIOR
A39: SAN CRISTOBAL JUNIO 2026
H40: .........................................
H41: FIRMA EMPLEADO

Sheet RAMIREZ
A1: COMISIÓN DE SERVICIO - VIÁTICOS Y GASTOS
A3: MINISTERIO DE SALUD - HOSPITAL SAN CRISTOBAL
A4: DIRECCION: COCHABAMBA 1456 - SAN CRISTOBAL
A5: AGENTE: RAMIREZ MARIA | J5: CARGO
A6: DESTINO: RAFAELA - SANTA FE | J6: ENFERMERA
A7: MISION: PACIENTES VARIOS | J7: ITEM | K7: SUELDO
A8: 46174
A10: SALIDA | D10: REGRESO | G10: VIÁTICO | I10: IMPORTE | J10: OBSERVACIONES
A11: DIA | B11: MES | C11: HORA | D11: DIA | E11: MES | F11: HORA | G11: DÍAS | H11: CUOTA
A12: 6 | B12: 6 | C12: 09,00 | D12: 6 | E12: 6 | F12: 16,00 | G12: 0.5 | H12: 84366 | I12: 42183
A13: 6 | B13: 6 | C13: 17,00 | D13: 6 | E13: 6 | F13: 23,45 | G13: 0.5 | H13: 84366 | I13: 42183
A14: 13 | B14: 6 | C14: 08,50 | D14: 13 | E14: 6 | F14: 15,00 | G14: 0.5 | H14: 84366 | I14: 42183
A15: 17 | B15: 6 | C15: 12,30 | D15: 17 | E15: 6 | F15: 19,00 | G15: 0.5 | H15: 84366 | I15: 42183
A16: 20 | B16: 6 | C16: 20,30 | D16: 21 | E16: 6 | F16: 03,30 | G16: 0.5 | H16: 84366 | I16: 42183
A17: 23 | B17: 6 | C17: 10,00 | D17: 23 | E17: 6 | F17: 20,05 | G17: 0.5 | H17: 84366 | I17: 42183
A18: 27 | B18: 6 | C18: 15,50 | D18: 27 | E18: 6 | F18: 22,00 | G18: 0.5 | H18: 84366 | I18: 42183
A19: 29 | B19: 6 | C19: 03,30 | D19: 29 | E19: 6 | F19: 10,00 | G19: 0.5 | H19: 84366 | I19: 42183
A20: 30 | B20: 6 | C20: 06,30 | D20: 30 | E20: 6 | F20: 13,30 | G20: 0.5 | H20: 84366 | I20: 42183
H32: TOTAL | I32: =SUM(I12:I31) -> 379647
A34: SON PESOS: TRESCIENTOS SETENTA Y NUEVE MIL SEISCIENTOS CUARENTA Y SIETE C/00 CTVOS.-
H36: .........................................
A37: RECIBI EL IMPORTE QUE ARROJA LA PLANILLA | H37: FIRMA SUPERIOR
A38: SAN CRISTOBAL JUNIO 2026
H39: .........................................
H40: FIRMA EMPLEADO

Sheet LOPEZE
A1: COMISIÓN DE SERVICIO - VIÁTICOS Y GASTOS
A3: MINISTERIO DE SALUD - HOSPITAL SAN CRISTOBAL
A4: DIRECCION: COCHABAMBA 1456 - SAN CRISTOBAL
A5: AGENTE: LOPEZ SALOME | J5: CARGO
A6: DESTINO: RAFAELA - SANTA FE | J6: ENFERMERA
A7: MISION: PACIENTES VARIOS | J7: ITEM | K7: SUELDO
A8: 46174
A10: SALIDA | D10: REGRESO | G10: VIÁTICO | I10: IMPORTE | J10: OBSERVACIONES
A11: DIA | B11: MES | C11: HORA | D11: DIA | E11: MES | F11: HORA | G11: DÍAS | H11: CUOTA
A12: 2 | B12: 6 | C12: 19,00 | D12: 3 | E12: 6 | F12: 01,00 | G12: 0.5 | H12: 84366 | I12: 42183
A13: 5 | B13: 6 | C13: 09,00 | D13: 5 | E13: 6 | F13: 15.15 | G13: 0.5 | H13: 84366 | I13: 42183
A14: 7 | B14: 6 | C14: 19,30 | D14: 8 | E14: 6 | F14: 02,00 | G14: 0.5 | H14: 84366 | I14: 42183
A15: 12 | B15: 6 | C15: 00,30 | D15: 12 | E15: 6 | F15: 07,00 | G15: 0.5 | H15: 84366 | I15: 42183
A16: 23 | B16: 6 | C16: 09,00 | D16: 23 | E16: 6 | F16: 15,20 | G16: 0.5 | H16: 84366 | I16: 42183
A17: 26 | B17: 6 | C17: 10,30 | D17: 26 | E17: 6 | F17: 21,30 | G17: 0.5 | H17: 84366 | I17: 42183
A18: 26 | B18: 6 | C18: 03,10 | D18: 26 | E18: 6 | F18: 09,20 | G18: 0.5 | H18: 84366 | I18: 42183
A19: 29 | B19: 6 | C19: 15,50 | D19: 29 | E19: 6 | F19: 22,00 | G19: 0.5 | H19: 84366 | I19: 42183
H33: TOTAL | I33: =SUM(I12:I32) -> 337464
A35: SON PESOS:TRESCIENTOS TREINTA Y SIETE MIL CUATROCIENTOS SESENTA Y CUATRO C/00 CTVOS.-
H37: .........................................
A38: RECIBI EL IMPORTE QUE ARROJA LA PLANILLA | H38: FIRMA SUPERIOR
A39: SAN CRISTOBAL JUNIO 2026
H40: .........................................
H41: FIRMA EMPLEADO

Sheet ACEBAL
A1: COMISIÓN DE SERVICIO - VIÁTICOS Y GASTOS
A3: MINISTERIO DE SALUD - HOSPITAL SAN CRISTOBAL
A4: DIRECCION: COCHABAMBA 1456 - SAN CRISTOBAL
A5: AGENTE: ACEBAL MICAELA | J5: CARGO
A6: DESTINO: RAFAELA - SANTA FE | J6: ENFERMERA
A7: MISION: PACIENTES VARIOS | J7: ITEM | K7: SUELDO
A8: 46143
A10: SALIDA | D10: REGRESO | G10: VIÁTICO | I10: IMPORTE | J10: OBSERVACIONES
A11: DIA | B11: MES | C11: HORA | D11: DIA | E11: MES | F11: HORA | G11: DÍAS | H11: CUOTA
A12: 6 | B12: 5 | C12: 12,45 | D12: 6 | E12: 5 | F12: 18,50 | G12: 0.5 | H12: 83166 | I12: 41583
A13: 15 | B13: 5 | C13: 12,30 | D13: 15 | E13: 5 | F13: 18,45 | G13: 0.5 | H13: 83166 | I13: 41583
H33: TOTAL | I33: =SUM(I12:I32) -> 83166
A35: SON PESOS:OCHENTA Y UTRES MIL CIENTO SESENTA Y SEIS C/00 CTVOS.
H37: FIRMA SUPERIOR
A38: ='ALEJANDRO J'!A40 -> RECIBI EL IMPORTE QUE ARROJA LA PLANILLA
A39: SAN CRISTOBAL MAYO 2026 | H39: .........................................
H40: FIRMA EMPLEADO

Sheet LOPEZ 
A1: COMISIÓN DE SERVICIO - VIÁTICOS Y GASTOS
A3: MINISTERIO DE SALUD - HOSPITAL SAN CRISTOBAL
A4: DIRECCION: COCHABAMBA 1456 - SAN CRISTOBAL
A5: AGENTE: LOPEZ JORGE | J5: CARGO
A6: DESTINO: MORTEROS | J6: CHOFER
A7: MISION: PACIENTES VARIOS | J7: ITEM | K7: SUELDO
A9: ='ALEJANDRO J'!A6:J6 -> 0
A10: SALIDA | D10: REGRESO | G10: VIÁTICO | I10: IMPORTE | J10: OBSERVACIONES
A11: DIA | B11: MES | C11: HORA | D11: DIA | E11: MES | F11: HORA | G11: DÍAS | H11: CUOTA
A12: 8 | B12: 2 | C12: 21,1 | D12: 9 | E12: 2 | F12: 01,2 | G12: 0.25 | H12: 60845 | I12: =H12*G12 -> 15211.25
H33: TOTAL | I33: =SUM(I12:I32) -> 15211.25
A35: SON PESOS: QUINCE MIL DOSCIENTOS ONCE C/25/C/100
I37: .......................................
I38: FIRMA SUPERIOR
A39: RECIBI EL IMPORTE QUE ARROJA LA PLANILLA
A40: ='ALEJANDRO J'!A41 -> SAN CRISTOBAL, JUNIO DE 2026 | I40: .......................................
I41: FIRMA EMPLEADO

Sheet  AVALOS VER
A1: COMISIÓN DE SERVICIO - VIÁTICOS Y GASTOS
A3: MINISTERIO DE SALUD - HOSPITAL SAN CRISTOBAL
A4: DIRECCION: COCHABAMBA 1456 - SAN CRISTOBAL
A5: AGENTE: AVALOS VERONICA | J5: CARGO
A6: DESTINO: RAFAELA - SANTA FE | J6: ENFERMERA
A7: MISION: PACIENTES VARIOS | J7: ITEM | K7: SUELDO
A8: 46082
A10: SALIDA | D10: REGRESO | G10: VIÁTICO | I10: IMPORTE | J10: OBSERVACIONES
A11: DIA | B11: MES | C11: HORA | D11: DIA | E11: MES | F11: HORA | G11: DÍAS | H11: CUOTA
A12: 20 | B12: 3 | C12: 06,00 | D12: 20 | E12: 3 | F12: 12,30 | G12: 0.5 | H12: 80166 | I12: 40083
A13: 20 | B13: 3 | C13: 11,50 | D13: 20 | E13: 3 | F13: 18,10 | G13: 0.5 | H13: 80166 | I13: 40083
A14: 23 | B14: 3 | C14: 13,00 | D14: 23 | E14: 3 | F14: 20,45 | G14: 0.5 | H14: 80166 | I14: 40083
A15: 24 | B15: 3 | C15: 19,10 | D15: 25 | E15: 3 | F15: 01,20 | G15: 0.5 | H15: 80166 | I15: 40083
A16: 25 | B16: 3 | C16: 07,00 | D16: 25 | E16: 3 | F16: 13,15 | G16: 0.5 | H16: 80166 | I16: 40083
H33: TOTAL | I33: =SUM(I12:I32) -> 200415
A35: SON PESOS:DOSCIENTOS MIL CUATROCIENTOS QUINCE C/00CTVOS.
H37: FIRMA SUPERIOR
A38: ='ALEJANDRO J'!A40 -> RECIBI EL IMPORTE QUE ARROJA LA PLANILLA
A39: SAN CRISTOBAL MARZO 2026 | H39: .........................................
H40: FIRMA EMPLEADO
G41: |

Sheet OVIEDO R
A1: COMISIÓN DE SERVICIO - VIÁTICOS Y GASTOS
A3: MINISTERIO DE SALUD - HOSPITAL SAN CRISTOBAL
A4: DIRECCION: COCHABAMBA 1456 - SAN CRISTOBAL
A5: AGENTE: OVIEDO ROSANA | J5: CARGO
A6: DESTINO: RAFAELA - SANTA FE | J6: ENFERMERA
A7: MISION: PACIENTES VARIOS | J7: ITEM | K7: SUELDO
A8: 46023
A10: SALIDA | D10: REGRESO | G10: VIÁTICO | I10: IMPORTE | J10: OBSERVACIONES
A11: DIA | B11: MES | C11: HORA | D11: DIA | E11: MES | F11: HORA | G11: DÍAS | H11: CUOTA
A12: 1 | B12: 1 | C12: 12.00 | D12: 1 | E12: 1 | F12: 18.00 | G12: 0.5 | H12: 72808 | I12: 36404
A13: 1 | B13: 1 | C13: 20.00 | D13: 2 | E13: 1 | F13: 02.10 | G13: 0.5 | H13: 72808 | I13: 36404
A14: 6 | B14: 1 | C14: 22.00 | D14: 7 | E14: 1 | F14: 05.00 | G14: 0.5 | H14: 72808 | I14: 36404
H33: TOTAL | I33: =SUM(I12:I32) -> 109212
A35: SON PESOS: CIENTO NUEVE MIL DOSCIENTOS DOCE C/00 CTVOS.-
I37: .........................................
I38: FIRMA SUPERIOR
A39: RECIBI EL IMPORTE QUE ARROJA LA PLANILLA
A40: SAN CRISTOBAL ENERO DE 2026 | I40: ........................................
I41: FIRMA EMPLEADO

Sheet MIRANDA S
A1: COMISIÓN DE SERVICIO - VIÁTICOS Y GASTOS
A3: MINISTERIO DE SALUD - HOSPITAL SAN CRISTOBAL
A4: DIRECCION: COCHABAMBA 1456 - SAN CRISTOBAL
A5: AGENTE: MIRANDA STELLA MARIS | J5: CARGO
A6: DESTINO: RAFAELA - SANTA FE | J6: ENFERMERA
A7: MISION: PACIENTES VARIOS | J7: ITEM | K7: SUELDO
A8: 46143
A10: SALIDA | D10: REGRESO | G10: VIÁTICO | I10: IMPORTE | J10: OBSERVACIONES
A11: DIA | B11: MES | C11: HORA | D11: DIA | E11: MES | F11: HORA | G11: DÍAS | H11: CUOTA
A12: 10 | B12: 5 | C12: 22,00 | D12: 11 | E12: 5 | F12: 4,30 | G12: 0.5 | H12: 83166 | I12: 41583
A13: 10 | B13: 5 | C13: 15,10 | D13: 10 | E13: 5 | F13: 21,20 | G13: 0.5 | H13: 83166 | I13: 41583
A14: 11 | B14: 5 | C14: 11,30 | D14: 11 | E14: 5 | F14: 18,00 | G14: 0.5 | H14: 83166 | I14: 41583
A15: 17 | B15: 5 | C15: 00,05 | D15: 17 | E15: 5 | F15: 06,10 | G15: 0.5 | H15: 83166 | I15: 41583
H33: TOTAL | I33: =SUM(I12:I32) -> 166332
A35: SON PESOS:CIENTO SESENTA Y SEIS MIL TRESCIENTOS TREINTA Y DOS C/00 CTVOS.-
I37: .........................................
I38: FIRMA SUPERIOR
A39: RECIBI EL IMPORTE QUE ARROJA LA PLANILLA
A40: SAN CRISTOBAL MAYO DE 2026 | I40: ........................................
I41: FIRMA EMPLEADO

Sheet VIVIANI
A1: COMISIÓN DE SERVICIO - VIÁTICOS Y GASTOS
A3: MINISTERIO DE SALUD - HOSPITAL SAN CRISTOBAL
A4: DIRECCION: COCHABAMBA 1456 - SAN CRISTOBAL
A5: AGENTE: VIVIANI ARACELI | J5: CARGO
A6: DESTINO: RAFAELA - SANTA FE | J6: ENFERMERA
A7: MISION: PACIENTES VARIOS | J7: ITEM | K7: SUELDO
A8: 46174
A9: ='ALEJANDRO J'!A6:J6 -> 0
A10: SALIDA | D10: REGRESO | G10: VIÁTICO | I10: IMPORTE | J10: OBSERVACIONES
A11: DIA | B11: MES | C11: HORA | D11: DIA | E11: MES | F11: HORA | G11: DÍAS | H11: CUOTA
A12: 5 | B12: 6 | C12: 17:00 | D12: 5 | E12: 6 | F12: 23,45 | G12: 0.5 | H12: 84366 | I12: 42183
A13: 18 | B13: 6 | C13: 17,15 | D13: 18 | E13: 6 | F13: 23,45 | G13: 0.5 | H13: 84366 | I13: 42183
H33: TOTAL | I33: =SUM(I12:I29) -> 84366
A35: SON PESOS: OCHENTA Y CUATRO MIL TRESCIENTOS SESENTA Y SEIS C/00 CTVOS.-
I37: ……………………………….
I38: FIRMA SUPERIOR
A39: RECIBI EL IMPORTE QUE ARROJA PLANILLA
A40: SAN CRISTOBALJUNIO 2026 | I40: …………………………….
I41: FIRMA EMPLEADO

Sheet MUGA
A1: COMISIÓN DE SERVICIO - VIÁTICOS Y GASTOS
A3: MINISTERIO DE SALUD - HOSPITAL SAN CRISTOBAL
A4: DIRECCION: COCHABAMBA 1456 - SAN CRISTOBAL
A5: AGENTE: MUGA ANA LAURA | J5: CARGO
A6: DESTINO: RAFAELA - SANTA FE | J6: ENFERMERA
A7: MISION: PACIENTES VARIOS | J7: ITEM | K7: SUELDO
A8: 45962
A9: ='ALEJANDRO J'!A6:J6 -> 0
A10: SALIDA | D10: REGRESO | G10: VIÁTICO | I10: IMPORTE | J10: OBSERVACIONES
A11: DIA | B11: MES | C11: HORA | D11: DIA | E11: MES | F11: HORA | G11: DÍAS | H11: CUOTA
A12: 25 | B12: 11 | C12: 10.00 | D12: 25 | E12: 11 | F12: 16.20 | G12: 0.5 | H12: 72151 | I12: =H12*G12 -> 36075.5
H33: TOTAL | I33: =SUM(I12:I29) -> 36075.5
A35: SON PESOS: TREINTA Y SEIS MIL SETENTA Y CINCO C/50 CTVOS.-
H37: .........................................
H38: FIRMA SUPERIOR
A39: RECIBI EL IMPORTE QUE ARROJA PLANILLA
A40: SAN CRISTOBAL NOVIEMBRE 2025 | H40: …………………………..
H41: FIRMA EMPLEADO

Sheet DOBANTON
A1: COMISIÓN DE SERVICIO - VIÁTICOS Y GASTOS
A3: MINISTERIO DE SALUD - HOSPITAL SAN CRISTOBAL
A4: DIRECCION: COCHABAMBA 1456 - SAN CRISTOBAL
A5: AGENTE: DOBANTON LAURA | J5: CARGO
A6: DESTINO: RAFAELA - SANTA FE | J6: ENFERMERA
A7: MISION: PACIENTES VARIOS | J7: ITEM | K7: SUELDO
A8: 46174
A9: ='ALEJANDRO J'!A6:J6 -> 0
A10: SALIDA | D10: REGRESO | G10: VIÁTICO | I10: IMPORTE | J10: OBSERVACIONES
A11: DIA | B11: MES | C11: HORA | D11: DIA | E11: MES | F11: HORA | G11: DÍAS | H11: CUOTA
A12: 21 | B12: 6 | C12: 22,15 | D12: 22 | E12: 6 | F12: 05,00 | G12: 0.5 | H12: 84366 | I12: 42183
A13: 26 | B13: 6 | C13: 03,00 | D13: 26 | E13: 6 | F13: 09,15 | G13: 0.5 | H13: 84366 | I13: 42183
H33: TOTAL | I33: =SUM(I12:I29) -> 84366
A35: SON PESOS: OCHENTA Y CUATRO MIL TRESCIENTOS SESENTA Y SEIS C/50 CTVOS.-
H37: .........................................
H38: FIRMA SUPERIOR
A39: RECIBI EL IMPORTE QUE ARROJA PLANILLA
A40: SAN CRISTOBAL JUNIO 2026 | H40: …………………………..
H41: FIRMA EMPLEADO

Sheet BERTUZZI S
A1: COMISIÓN DE SERVICIO - VIÁTICOS Y GASTOS
A3: MINISTERIO DE SALUD - HOSPITAL SAN CRISTOBAL
A4: DIRECCION: COCHABAMBA 1456 - SAN CRISTOBAL
A5: AGENTE: DRA BERTUZZI SOFIA | J5: CARGO
A6: DESTINO: RAFAELA - SANTA FE | J6: MEDICO
A7: MISION: COMISION DE SERVICIO | J7: ITEM | K7: SUELDO
A8: 46143
A10: SALIDA | D10: REGRESO | G10: VIÁTICO | I10: IMPORTE | J10: OBSERVACIONES
A11: DIA | B11: MES | C11: HORA | D11: DIA | E11: MES | F11: HORA | G11: DÍAS | H11: CUOTA
A12: 10 | B12: 5 | C12: 15,15 | D12: 10 | E12: 5 | F12: 21,30 | G12: 0.5 | H12: 83166 | I12: =H12*G12 -> 41583
A22: GASTOS SIN DOCUMENTAR- 10%
A23: FECHA | C23: N° DE | E23: DETALLE
C24: COMPROBANTE
A31: TOTAL $ | I31: =SUM(I12:I30) -> 41583
A35: SON PESOS: CUARENTA Y UN MIL QUINIENTOS OCHENTA Y TRES C/00 CTVOS
A37: RECIBI EL IMPORTE QUE ARROJA LA PLANILLA | I37: ...................................
A38: SAN CRISTOBAL MAYO 2026 | I38: FIRMA SUPERIOR
I40: ...................................
I41: FIRMA EMPLEADO

Sheet DIAZ BELEN
A1: COMISIÓN DE SERVICIO - VIÁTICOS Y GASTOS
A3: MINISTERIO DE SALUD - HOSPITAL SAN CRISTOBAL
A4: DIRECCION: COCHABAMBA 1456 - SAN CRISTOBAL
A5: AGENTE: DIAZ BELEN | J5: CARGO
A6: DESTINO: RAFAELA - SANTA FE | J6: MEDICO
A7: MISION: COMISION DE SERVICIO | J7: ITEM | K7: SUELDO
A8: 46143
A9: =I19='ALEJANDRO J'!A6:J6 -> TRUE
A10: SALIDA | D10: REGRESO | G10: VIÁTICO | I10: IMPORTE | J10: OBSERVACIONES
A11: DIA | B11: MES | C11: HORA | D11: DIA | E11: MES | F11: HORA | G11: DÍAS | H11: CUOTA
A12: 21 | B12: 5 | C12: 3,30 | D12: 21 | E12: 5 | F12: 10,00 | G12: 0.5 | H12: 83166 | I12: =H12*G12 -> 41583
A22: GASTOS SIN DOCUMENTAR- 10%
A23: FECHA | C23: N° DE | E23: DETALLE
C24: COMPROBANTE
A31: TOTAL $ | I31: =SUM(I12:I30) -> 41583
A35: SON PESOSCUARENTA Y UN MIL QUINIENTOS OCHENTA Y TRES C/00 CTVOS.-
A37: RECIBI EL IMPORTE QUE ARROJA LA PLANILLA | I37: ...................................
A38: SAN CRISTOBAL MAYO 2026 | I38: FIRMA SUPERIOR
I40: ...................................
I41: FIRMA EMPLEADO

Sheet BORSINI
A1: COMISIÓN DE SERVICIO - VIÁTICOS Y GASTOS
A3: MINISTERIO DE SALUD - HOSPITAL SAN CRISTOBAL
A4: DIRECCION: COCHABAMBA 1456 - SAN CRISTOBAL
A5: AGENTE: DR BORSINI ARMANDO | J5: CARGO
A6: DESTINO: RAFAELA - SANTA FE | J6: MEDICO
A7: MISION: COMISION DE SERVICIO | J7: ITEM | K7: SUELDO
A8: JUNIO
A10: SALIDA | D10: REGRESO | G10: VIÁTICO | I10: IMPORTE | J10: OBSERVACIONES
A11: DIA | B11: MES | C11: HORA | D11: DIA | E11: MES | F11: HORA | G11: DÍAS | H11: CUOTA
A12: 21 | B12: 6 | C12: 15.20 | D12: 21 | E12: 6 | F12: 22,00 | G12: 0.5 | H12: 84366 | I12: =H12*G12 -> 42183
A22: GASTOS SIN DOCUMENTAR- 10%
A23: FECHA | C23: N° DE | E23: DETALLE
C24: COMPROBANTE
A31: TOTAL $ | I31: =SUM(I12:I30) -> 42183
A35: SON PESOS: CUARENTA Y DOS MIL CIENTO OCHENTA Y TRES C/00 CTVOS.-
A37: RECIBI EL IMPORTE QUE ARROJA LA PLANILLA | I37: ...................................
A38: SAN CRISTOBAL JUNIO 2026 | I38: FIRMA SUPERIOR
I40: ...................................
I41: FIRMA EMPLEADO

Sheet CATTANEO
A1: COMISIÓN DE SERVICIO - VIÁTICOS Y GASTOS
A3: MINISTERIO DE SALUD - HOSPITAL SAN CRISTOBAL
A4: DIRECCION: COCHABAMBA 1456 - SAN CRISTOBAL
A5: AGENTE: DR CATTANEO RICARDO | J5: CARGO
A6: DESTINO: RAFAELA - SANTA FE | J6: MEDICO
A7: MISION: COMISION DE SERVICIO | J7: ITEM | K7: SUELDO
A8: JUNIO
A9: =I19='ALEJANDRO J'!A6:J6 -> TRUE
A10: SALIDA | D10: REGRESO | G10: VIÁTICO | I10: IMPORTE | J10: OBSERVACIONES
A11: DIA | B11: MES | C11: HORA | D11: DIA | E11: MES | F11: HORA | G11: DÍAS | H11: CUOTA
A12: 6 | B12: 6 | C12: 09,00 | D12: 6 | E12: 6 | F12: 16,00 | G12: 0.5 | H12: 84366 | I12: =H12*G12 -> 42183
A22: GASTOS SIN DOCUMENTAR- 10%
A23: FECHA | C23: N° DE | E23: DETALLE
C24: COMPROBANTE
A31: TOTAL $ | I31: =SUM(I12:I30) -> 42183
A35: SON PESOS: CUARENTA Y DOS MIL CIENTO OCHENTA Y TRES C/00 CTVOS.
A37: RECIBI EL IMPORTE QUE ARROJA LA PLANILLA | I37: ...................................
A38: SAN CRISTOBAL JUNIO 2026 | I38: FIRMA SUPERIOR
I40: ...................................
I41: FIRMA EMPLEADO

Sheet CROISANT
A1: COMISIÓN DE SERVICIO - VIÁTICOS Y GASTOS
A3: MINISTERIO DE SALUD - HOSPITAL SAN CRISTOBAL
A4: DIRECCION: COCHABAMBA 1456 - SAN CRISTOBAL
A5: AGENTE: DR CROISANT ALEJANDRO | J5: CARGO
A6: DESTINO: RAFAELA - SANTA FE | J6: MEDICO
A7: MISION: COMISION DE SERVICIO | J7: ITEM | K7: SUELDO
A8: 46113
A9: =I19='ALEJANDRO J'!A6:J6 -> TRUE
A10: SALIDA | D10: REGRESO | G10: VIÁTICO | I10: IMPORTE | J10: OBSERVACIONES
A11: DIA | B11: MES | C11: HORA | D11: DIA | E11: MES | F11: HORA | G11: DÍAS | H11: CUOTA
A12: 16 | B12: 4 | C12: 16,00 | D12: 16 | E12: 4 | F12: 22,20 | G12: 0.5 | H12: 81166 | I12: =H12*G12 -> 40583
A22: GASTOS SIN DOCUMENTAR- 10%
A23: FECHA | C23: N° DE | E23: DETALLE
C24: COMPROBANTE
A31: TOTAL $ | I31: =SUM(I12:I30) -> 40583
A35: SON PESOS:CUARENTA MIL QUINIENTOS OCHENTA Y TRES C/00 CTVOS.-
A37: RECIBI EL IMPORTE QUE ARROJA LA PLANILLA | I37: ...................................
A38: SAN CRISTOBAL ABRIL 2026 | I38: FIRMA SUPERIOR
I40: ...................................
I41: FIRMA EMPLEADO

Sheet BACAJIMENEZ
A1: COMISIÓN DE SERVICIO - VIÁTICOS Y GASTOS
A3: MINISTERIO DE SALUD - HOSPITAL SAN CRISTOBAL
A4: DIRECCION: COCHABAMBA 1456 - SAN CRISTOBAL
A5: AGENTE: DR BACA JIMENEZ DENAS | J5: CARGO
A6: DESTINO: RAFAELA - SANTA FE | J6: MEDICO
A7: MISION: COMISION DE SERVICIO | J7: ITEM | K7: SUELDO
A8: 46174
A9: =I19='ALEJANDRO J'!A6:J6 -> TRUE
A10: SALIDA | D10: REGRESO | G10: VIÁTICO | I10: IMPORTE | J10: OBSERVACIONES
A11: DIA | B11: MES | C11: HORA | D11: DIA | E11: MES | F11: HORA | G11: DÍAS | H11: CUOTA
A12: 25 | B12: 6 | C12: 00,40 | D12: 25 | E12: 6 | F12: 07,00 | G12: 0.5 | H12: 84366 | I12: =H12*G12 -> 42183
A22: GASTOS SIN DOCUMENTAR- 10%
A23: FECHA | C23: N° DE | E23: DETALLE
C24: COMPROBANTE
A31: TOTAL $ | I31: =SUM(I12:I30) -> 42183
A35: SON PESOS: CUARENTA Y DOS MIL CIENTO OCHENTA Y TRES C/00 CTVOS.-
A37: RECIBI EL IMPORTE QUE ARROJA LA PLANILLA | I37: ...................................
A38: SAN CRISTOBAL JUNIO 2026 | I38: FIRMA SUPERIOR
I40: ...................................
I41: FIRMA EMPLEADO

Sheet DE NAPOLI
A1: COMISIÓN DE SERVICIO - VIÁTICOS Y GASTOS
A3: MINISTERIO DE SALUD - HOSPITAL SAN CRISTOBAL
A4: DIRECCION: COCHABAMBA 1456 - SAN CRISTOBAL
A5: AGENTE: DRA DENAPOLI CLAUDIA | J5: CARGO
A6: DESTINO: RAFAELA - SANTA FE | J6: MEDICO
A7: MISION: COMISION DE SERVICIO | J7: ITEM | K7: SUELDO
A8: JUNIO
A10: SALIDA | D10: REGRESO | G10: VIÁTICO | I10: IMPORTE | J10: OBSERVACIONES
A11: DIA | B11: MES | C11: HORA | D11: DIA | E11: MES | F11: HORA | G11: DÍAS | H11: CUOTA
A12: 11 | B12: 6 | C12: 10,00 | D12: 11 | E12: 6 | F12: 16,10 | G12: 0.5 | H12: 84366 | I12: =H12*G12 -> 42183
A22: GASTOS SIN DOCUMENTAR- 10%
A23: FECHA | C23: N° DE | E23: DETALLE
C24: COMPROBANTE
A31: TOTAL $ | I31: =SUM(I12:I30) -> 42183
A35: SON PESOS: CUARENTA Y DOS MIL CIENTO OCHENTA Y TRES C/00 CTVOS.-
A37: RECIBI EL IMPORTE QUE ARROJA LA PLANILLA | I37: ...................................
A38: SAN CRISTOBAL JUNIO 2026 | I38: FIRMA SUPERIOR
I40: ...................................
I41: FIRMA EMPLEADO

Sheet ARGAÑARAZ
A1: COMISIÓN DE SERVICIO - VIÁTICOS Y GASTOS
A3: MINISTERIO DE SALUD - HOSPITAL SAN CRISTOBAL
A4: DIRECCION: COCHABAMBA 1456 - SAN CRISTOBAL
A5: AGENTE: ARGAÑARAZ LAURA | J5: CARGO
A6: DESTINO: RAFAELA - SANTA FE | J6: MEDICA
A7: MISION: PACIENTES VARIOS | J7: ITEM | K7: SUELDO
A8: 45992
A9: =I19='ALEJANDRO J'!A6:J6 -> TRUE
A10: SALIDA | D10: REGRESO | G10: VIÁTICO | I10: IMPORTE | J10: OBSERVACIONES
A11: DIA | B11: MES | C11: HORA | D11: DIA | E11: MES | F11: HORA | G11: DÍAS | H11: CUOTA
A12: 20 | B12: 12 | C12: 23.20 | D12: 21 | E12: 12 | F12: 05.35 | G12: 0.5 | H12: 72808 | I12: =H12*G12 -> 36404
A22: GASTOS SIN DOCUMENTAR- 10%
A23: FECHA | C23: N° DE | E23: DETALLE
C24: COMPROBANTE
A31: TOTAL $ | I31: =SUM(I12:I30) -> 36404
A35: SON PESOS: TRESCIENTOS SEIS MIL CUATROSCIENTOS CUATRO C/ 00CTVOS.-
A37: RECIBI EL IMPORTE QUE ARROJA LA PLANILLA | I37: ...................................
A38: SAN CRISTOBAL DICIEMBRE 2025 | I38: FIRMA SUPERIOR
I40: ...................................
I41: FIRMA EMPLEADO

Sheet AMBROSINI
A1: COMISIÓN DE SERVICIO - VIÁTICOS Y GASTOS
A3: MINISTERIO DE SALUD - HOSPITAL SAN CRISTOBAL
A4: DIRECCION: COCHABAMBA 1456 - SAN CRISTOBAL
A5: AGENTE: DRA VALLI LARA | J5: CARGO
A6: DESTINO: RAFAELA - SANTA FE | J6: MEDICO
A7: MISION: PACIENTES VARIOS | J7: ITEM | K7: SUELDO
A8: 46174
A10: SALIDA | D10: REGRESO | G10: VIÁTICO | I10: IMPORTE | J10: OBSERVACIONES
A11: DIA | B11: MES | C11: HORA | D11: DIA | E11: MES | F11: HORA | G11: DÍAS | H11: CUOTA
A12: 26 | B12: 6 | C12: 03,10 | D12: 26 | E12: 6 | F12: 09,20 | G12: 0.5 | H12: 84366 | I12: =H12*G12 -> 42183
A22: GASTOS SIN DOCUMENTAR- 10%
A23: FECHA | C23: N° DE | E23: DETALLE
C24: COMPROBANTE
A31: TOTAL $ | I31: =SUM(I12:I30) -> 42183
A35: SON PESOS: CUARENTA Y DOS MIL CIENTO OCHENTA Y TRES C/00
A37: RECIBI EL IMPORTE QUE ARROJA LA PLANILLA | I37: ...................................
A38: SAN CRISTOBAL EJUNIO 2026 | I38: FIRMA SUPERIOR
I40: ...................................
I41: FIRMA EMPLEADO

Sheet FERNANDEZ N
A1: COMISIÓN DE SERVICIO - VIÁTICOS Y GASTOS
A3: MINISTERIO DE SALUD - HOSPITAL SAN CRISTOBAL
A4: DIRECCION: COCHABAMBA 1456 - SAN CRISTOBAL
A5: AGENTE: DRA FERNANDEZ NATALIA | J5: CARGO
A6: DESTINO: RAFAELA - SANTA FE | J6: MEDICO
A7: MISION: PACIENTES VARIOS | J7: ITEM | K7: SUELDO
A8: 46143
A10: SALIDA | D10: REGRESO | G10: VIÁTICO | I10: IMPORTE | J10: OBSERVACIONES
A12: 10 | B12: 5 | C12: 22,00 | D12: 11 | E12: 5 | F12: 4,30 | G12: 0.5 | H12: 83166 | I12: =H12*G12 -> 41583
A22: GASTOS SIN DOCUMENTAR- 10%
A23: FECHA | C23: N° DE | E23: DETALLE
C24: COMPROBANTE
A31: TOTAL $ | I31: =SUM(I12:I30) -> 41583
A35: SON PESOS: CUARENTA Y UN MIL QUINIENTOS OCHENTA Y TRES C/00
A37: RECIBI EL IMPORTE QUE ARROJA LA PLANILLA | I37: ...................................
A38: SAN CRISTOBAL MAYO 2026 | I38: FIRMA SUPERIOR
I40: ...................................
I41: FIRMA EMPLEADO

Sheet NICOLA
A1: COMISIÓN DE SERVICIO - VIÁTICOS Y GASTOS
A3: MINISTERIO DE SALUD - HOSPITAL SAN CRISTOBAL
A4: DIRECCION: COCHABAMBA 1456 - SAN CRISTOBAL
A5: AGENTE: DRA NICOLA CAMILA | J5: CARGO
A6: DESTINO: RAFAELA - SANTA FE | J6: MEDICO
A7: MISION: PACIENTES VARIOS | J7: ITEM | K7: SUELDO
A8: JUNIO
A10: SALIDA | D10: REGRESO | G10: VIÁTICO | I10: IMPORTE | J10: OBSERVACIONES
A11: DIA | B11: MES | C11: HORA | D11: DIA | E11: MES | F11: HORA | G11: DÍAS | H11: CUOTA
A12: 30 | B12: 6 | C12: 06,30 | D12: 30 | E12: 6 | F12: 13,30 | G12: 0.5 | H12: 84366 | I12: =H12*G12 -> 42183
A22: GASTOS SIN DOCUMENTAR- 10%
A23: FECHA | C23: N° DE | E23: DETALLE
C24: COMPROBANTE
A31: TOTAL $ | I31: =SUM(I12:I30) -> 42183
A34: SON PESOS:CUARENTA Y DOS MIL CIENTO OCHENTA Y TRES C/00 CTVOS.
A36: RECIBI EL IMPORTE QUE ARROJA LA PLANILLA | I36: ...................................
A37: SAN CRISTOBAL JUNIO 2026
I39: ...................................
I40: FIRMA EMPLEADO

Sheet SUAREZ
A1: COMISIÓN DE SERVICIO - VIÁTICOS Y GASTOS
A3: MINISTERIO DE SALUD - HOSPITAL SAN CRISTOBAL
A4: DIRECCION: COCHABAMBA 1456 - SAN CRISTOBAL
A5: AGENTE: SUAREZ JUDITH | J5: CARGO
A6: DESTINO: RAFAELA - SANTA FE | J6: OBSTETRA
A7: MISION: PACIENTES VARIOS | J7: ITEM | K7: SUELDO
A8: 46023
A10: SALIDA | D10: REGRESO | G10: VIÁTICO | I10: IMPORTE | J10: OBSERVACIONES
A11: DIA | B11: MES | C11: HORA | D11: DIA | E11: MES | F11: HORA | G11: DÍAS | H11: CUOTA
A12: 23 | B12: 1 | C12: 14,00 | D12: 23 | E12: 1 | F12: 20,30 | G12: 0.5 | H12: 72808 | I12: =H12*G12 -> 36404
A22: GASTOS SIN DOCUMENTAR- 10%
A23: FECHA | C23: N° DE | E23: DETALLE
C24: COMPROBANTE
A31: TOTAL $ | I31: =SUM(I12:I30) -> 36404
A35: SON PESOS: TREINTA Y SEIS MIL CUATROSCIENTOS CUATRO C/00
A37: RECIBI EL IMPORTE QUE ARROJA LA PLANILLA | I37: ...................................
A38: SAN CRISTOBAL ENERO 2026 | I38: FIRMA SUPERIOR
I40: ...................................
I41: FIRMA EMPLEADO

Sheet EYVASTRE
A1: COMISIÓN DE SERVICIO - VIÁTICOS Y GASTOS
A3: MINISTERIO DE SALUD - HOSPITAL SAN CRISTOBAL
A4: DIRECCION: COCHABAMBA 1456 - SAN CRISTOBAL
A5: AGENTE: DR EYVASTRE MARIELA | J5: CARGO
A6: DESTINO: RAFAELA - SANTA FE | J6: MEDICO
A7: MISION: COMISION DE SERVICIO | J7: ITEM | K7: SUELDO
A8: JUNIO
A9: =I19='ALEJANDRO J'!A6:J6 -> TRUE
A10: SALIDA | D10: REGRESO | G10: VIÁTICO | I10: IMPORTE | J10: OBSERVACIONES
A11: DIA | B11: MES | C11: HORA | D11: DIA | E11: MES | F11: HORA | G11: DÍAS | H11: CUOTA
A12: 25 | B12: 6 | C12: 03,45 | D12: 25 | E12: 6 | F12: 10,00 | G12: 0.5 | H12: 84366 | I12: =H12*G12 -> 42183
A22: GASTOS SIN DOCUMENTAR- 10%
A23: FECHA | C23: N° DE | E23: DETALLE
C24: COMPROBANTE
A31: TOTAL $ | I31: =SUM(I12:I30) -> 42183
A35: SON PESOS: CUARENTA Y DOS MIL CIENTO OCHENTA Y TRES C/00 CTVOS.-
A37: RECIBI EL IMPORTE QUE ARROJA LA PLANILLA | I37: ...................................
A38: SAN CRISTOBAL JUNIO 2025 | I38: FIRMA SUPERIOR
I40: ...................................
I41: FIRMA EMPLEADO

Sheet OBATTA
A1: COMISIÓN DE SERVICIO - VIÁTICOS Y GASTOS
A3: MINISTERIO DE SALUD - HOSPITAL SAN CRISTOBAL
A4: DIRECCION: COCHABAMBA 1456 - SAN CRISTOBAL
A5: AGENTE: DR OBATTA PABLO | J5: CARGO
A6: DESTINO: RAFAELA - SANTA FE | J6: MEDICO
A7: MISION: COMISION DE SERVICIO | J7: ITEM | K7: SUELDO
A8: 46082
A10: SALIDA | D10: REGRESO | G10: VIÁTICO | I10: IMPORTE | J10: OBSERVACIONES
A11: DIA | B11: MES | C11: HORA | D11: DIA | E11: MES | F11: HORA | G11: DÍAS | H11: CUOTA
A12: 14 | B12: 3 | C12: 02,10 | D12: 14 | E12: 3 | F12: 08,30 | G12: 0.5 | H12: 80166 | I12: =H12*G12 -> 40083
A22: GASTOS SIN DOCUMENTAR- 10%
A23: FECHA | C23: N° DE | E23: DETALLE
C24: COMPROBANTE
A31: TOTAL $ | I31: =SUM(I12:I30) -> 40083
A35: SON PESOS:CUARENTA MIL OCHENTA Y TRES C/00CTVOS.
A37: RECIBI EL IMPORTE QUE ARROJA LA PLANILLA | I37: ...................................
A38: SAN CRISTOBAL MARZO 2026 | I38: FIRMA SUPERIOR
I40: ...................................
I41: FIRMA EMPLEADO

Sheet VASCHUK
A1: COMISIÓN DE SERVICIO - VIÁTICOS Y GASTOS
A3: MINISTERIO DE SALUD - HOSPITAL SAN CRISTOBAL
A4: DIRECCION: COCHABAMBA 1456 - SAN CRISTOBAL
A5: AGENTE: DR VASCHUK NICOLAS | J5: CARGO
A6: DESTINO: RAFAELA - SANTA FE | J6: MEDICO
A7: MISION: PACIENTES VARIOS | J7: ITEM | K7: SUELDO
A8: 46143
A10: SALIDA | D10: REGRESO | G10: VIÁTICO | I10: IMPORTE | J10: OBSERVACIONES
A11: DIA | B11: MES | C11: HORA | D11: DIA | E11: MES | F11: HORA | G11: DÍAS | H11: CUOTA
A12: 4 | B12: 5 | C12: 2,30 | D12: 4 | E12: 5 | F12: 9,00 | G12: 0.5 | H12: 83166 | I12: 41583
A13: 17 | B13: 5 | C13: 12,55 | D13: 17 | E13: 5 | F13: 19,00 | G13: 0.5 | H13: 83166 | I13: 41583
A22: GASTOS SIN DOCUMENTAR- 10%
A23: FECHA | C23: N° DE | E23: DETALLE
C24: COMPROBANTE
A31: TOTAL $ | I31: =SUM(I12:I30) -> 83166
A35: SON PESOS: OCHENTA Y TRES MIL CIENTO SESENTA Y SEIS C/00
A37: RECIBI EL IMPORTE QUE ARROJA LA PLANILLA | I37: ...................................
